
2023-05-22 11:43:27,532 INFO: App startup [in app/__init__.py:52]
2023-05-22 11:43:45,509 INFO: App startup [in app/__init__.py:52]
2023-05-22 11:44:09,086 INFO: App startup [in app/__init__.py:52]
2023-05-22 11:46:19,600 INFO: App startup [in app/__init__.py:52]
2023-05-22 11:46:27,894 INFO: App startup [in app/__init__.py:52]
2023-05-22 11:46:40,266 INFO: 3 questions was added to database [in app/routes.py:106]
2023-05-22 11:47:02,450 INFO: 1 questions was added to database [in app/routes.py:106]
2023-05-22 14:01:59,588 INFO: App startup [in app/__init__.py:43]
2023-05-22 14:03:16,119 INFO: 3 questions was added to database [in app/routes.py:106]
2023-05-22 14:03:16,120 ERROR: Exception on /api/questions [POST] [in flask/app.py:1414]
Traceback (most recent call last):
  File "/home/dave/DEV/TestTasks/Bewise/Questions/venv/lib/python3.11/site-packages/flask/app.py", line 2190, in wsgi_app
    response = self.full_dispatch_request()
               ^^^^^^^^^^^^^^^^^^^^^^^^^^^^
  File "/home/dave/DEV/TestTasks/Bewise/Questions/venv/lib/python3.11/site-packages/flask/app.py", line 1486, in full_dispatch_request
    rv = self.handle_user_exception(e)
         ^^^^^^^^^^^^^^^^^^^^^^^^^^^^^
  File "/home/dave/DEV/TestTasks/Bewise/Questions/venv/lib/python3.11/site-packages/flask/app.py", line 1484, in full_dispatch_request
    rv = self.dispatch_request()
         ^^^^^^^^^^^^^^^^^^^^^^^
  File "/home/dave/DEV/TestTasks/Bewise/Questions/venv/lib/python3.11/site-packages/flask/app.py", line 1469, in dispatch_request
    return self.ensure_sync(self.view_functions[rule.endpoint])(**view_args)
           ^^^^^^^^^^^^^^^^^^^^^^^^^^^^^^^^^^^^^^^^^^^^^^^^^^^^^^^^^^^^^^^^^
  File "/home/dave/DEV/TestTasks/Bewise/Questions/app/routes.py", line 107, in get_question
    return last_question.as_dict(), 201
           ^^^^^^^^^^^^^^^^^^^^^
AttributeError: 'NoneType' object has no attribute 'as_dict'
2023-05-22 14:04:45,527 INFO: App startup [in app/__init__.py:43]
2023-05-22 14:04:50,027 INFO: 3 questions was added to database [in app/routes.py:106]
2023-05-22 14:05:48,443 INFO: 3 questions was added to database [in app/routes.py:106]
2023-05-22 17:16:00,949 INFO: App startup [in app/__init__.py:45]
2023-05-22 17:16:00,965 INFO: Database connection not established! [in app/__init__.py:52]
2023-05-22 17:17:20,109 INFO: App startup [in app/__init__.py:45]
2023-05-22 17:17:20,109 INFO: Database connection not established! [in app/__init__.py:52]
2023-05-22 17:17:58,791 INFO: App startup [in app/__init__.py:45]
2023-05-22 17:17:58,792 INFO: Database connection not established! [in app/__init__.py:52]
2023-05-22 17:18:26,827 INFO: App startup [in app/__init__.py:45]
2023-05-22 17:18:26,827 INFO: Database connection not established! [in app/__init__.py:52]
2023-05-22 17:19:18,614 INFO: App startup [in app/__init__.py:45]
2023-05-22 17:20:12,336 INFO: App startup [in app/__init__.py:45]
2023-05-22 17:20:39,510 INFO: App startup [in app/__init__.py:45]
2023-05-23 17:00:43,081 INFO: App startup [in app/__init__.py:42]
2023-05-23 17:03:04,406 INFO: App startup [in app/__init__.py:42]
2023-05-23 17:05:37,755 ERROR: Exception on /api/new-user/2 [POST] [in flask/app.py:1414]
Traceback (most recent call last):
  File "/home/dave/DEV/TestTasks/Bewise/WAVtoMP3/venv/lib/python3.11/site-packages/flask/app.py", line 2190, in wsgi_app
    response = self.full_dispatch_request()
               ^^^^^^^^^^^^^^^^^^^^^^^^^^^^
  File "/home/dave/DEV/TestTasks/Bewise/WAVtoMP3/venv/lib/python3.11/site-packages/flask/app.py", line 1486, in full_dispatch_request
    rv = self.handle_user_exception(e)
         ^^^^^^^^^^^^^^^^^^^^^^^^^^^^^
  File "/home/dave/DEV/TestTasks/Bewise/WAVtoMP3/venv/lib/python3.11/site-packages/flask/app.py", line 1484, in full_dispatch_request
    rv = self.dispatch_request()
         ^^^^^^^^^^^^^^^^^^^^^^^
  File "/home/dave/DEV/TestTasks/Bewise/WAVtoMP3/venv/lib/python3.11/site-packages/flask/app.py", line 1469, in dispatch_request
    return self.ensure_sync(self.view_functions[rule.endpoint])(**view_args)
           ^^^^^^^^^^^^^^^^^^^^^^^^^^^^^^^^^^^^^^^^^^^^^^^^^^^^^^^^^^^^^^^^^
TypeError: create_user() got an unexpected keyword argument 'user'
2023-05-23 17:05:53,004 ERROR: Exception on /api/new-user/q [POST] [in flask/app.py:1414]
Traceback (most recent call last):
  File "/home/dave/DEV/TestTasks/Bewise/WAVtoMP3/venv/lib/python3.11/site-packages/flask/app.py", line 2190, in wsgi_app
    response = self.full_dispatch_request()
               ^^^^^^^^^^^^^^^^^^^^^^^^^^^^
  File "/home/dave/DEV/TestTasks/Bewise/WAVtoMP3/venv/lib/python3.11/site-packages/flask/app.py", line 1486, in full_dispatch_request
    rv = self.handle_user_exception(e)
         ^^^^^^^^^^^^^^^^^^^^^^^^^^^^^
  File "/home/dave/DEV/TestTasks/Bewise/WAVtoMP3/venv/lib/python3.11/site-packages/flask/app.py", line 1484, in full_dispatch_request
    rv = self.dispatch_request()
         ^^^^^^^^^^^^^^^^^^^^^^^
  File "/home/dave/DEV/TestTasks/Bewise/WAVtoMP3/venv/lib/python3.11/site-packages/flask/app.py", line 1469, in dispatch_request
    return self.ensure_sync(self.view_functions[rule.endpoint])(**view_args)
           ^^^^^^^^^^^^^^^^^^^^^^^^^^^^^^^^^^^^^^^^^^^^^^^^^^^^^^^^^^^^^^^^^
TypeError: create_user() got an unexpected keyword argument 'user'
2023-05-23 18:14:38,330 INFO: App startup [in app/__init__.py:44]
2023-05-23 18:15:02,238 INFO: App startup [in app/__init__.py:44]
2023-05-23 18:15:07,851 INFO: App startup [in app/__init__.py:44]
2023-05-23 18:15:12,679 INFO: App startup [in app/__init__.py:44]
2023-05-23 18:16:50,022 INFO: App startup [in app/__init__.py:44]
2023-05-23 18:16:50,034 ERROR: (in table 'users', column 'uuid'): Compiler <sqlalchemy.dialects.sqlite.base.SQLiteTypeCompiler object at 0x7f62eb540310> can't render element of type UUID [in manage.py:16]
2023-05-23 18:18:22,766 INFO: App startup [in app/__init__.py:44]
2023-05-23 18:18:22,776 ERROR: (in table 'users', column 'uuid'): Compiler <sqlalchemy.dialects.sqlite.base.SQLiteTypeCompiler object at 0x7f35be344250> can't render element of type UUID [in manage.py:16]
